/pool/advay/vxs/.venv310/bin/python3.10: can't open file '/pool/advay/vxs/python/Experiments/representation_parallel.py': [Errno 2] No such file or directory
E0812 12:17:14.920000 48613 torch/distributed/elastic/multiprocessing/api.py:869] failed (exitcode: 2) local_rank: 0 (pid: 48662) of binary: /pool/advay/vxs/.venv310/bin/python3.10
Traceback (most recent call last):
  File "/pool/advay/vxs/.venv310/bin/torchrun", line 8, in <module>
    sys.exit(main())
  File "/pool/advay/vxs/.venv310/lib/python3.10/site-packages/torch/distributed/elastic/multiprocessing/errors/__init__.py", line 355, in wrapper
    return f(*args, **kwargs)
  File "/pool/advay/vxs/.venv310/lib/python3.10/site-packages/torch/distributed/run.py", line 918, in main
    run(args)
  File "/pool/advay/vxs/.venv310/lib/python3.10/site-packages/torch/distributed/run.py", line 909, in run
    elastic_launch(
  File "/pool/advay/vxs/.venv310/lib/python3.10/site-packages/torch/distributed/launcher/api.py", line 138, in __call__
    return launch_agent(self._config, self._entrypoint, list(args))
  File "/pool/advay/vxs/.venv310/lib/python3.10/site-packages/torch/distributed/launcher/api.py", line 269, in launch_agent
    raise ChildFailedError(
torch.distributed.elastic.multiprocessing.errors.ChildFailedError: 
============================================================
representation_parallel.py FAILED
------------------------------------------------------------
Failures:
  <NO_OTHER_FAILURES>
------------------------------------------------------------
Root Cause (first observed failure):
[0]:
  time      : 2025-08-12_12:17:14
  host      : sampo
  rank      : 0 (local_rank: 0)
  exitcode  : 2 (pid: 48662)
  error_file: <N/A>
  traceback : To enable traceback see: https://pytorch.org/docs/stable/elastic/errors.html
============================================================
